Workbook

Sheet Read Me
A1: ضماناتي (Damanaty) — PMO Workbook — Read Me
B4: Prepared for: | C4: CEO · Investors · Project Manager · Development Team · Product Owner
B5: Report date basis: | C5: 2026-07-26 (=TODAY() in formulas; all overdue/health/weekly figures move automatically)
B7: Color Legend
B8: Blue text | C8: Editable input cell — safe to type over (Status, dates, owner, notes, etc.)
B9: Black text | C9: Automatic formula — do not overwrite
C10: Status = Completed
C11: Status = In Progress (Design / Development / Testing / Review)
C12: Status = Planning
C13: Status = Blocked
C14: Priority / Risk = Critical, or task is Overdue
C15: Status = Not Started / Cancelled
B17: Sheet Guide
B18: Executive Dashboard | C18: KPIs, project health traffic light, and 6 live charts. Everything here recalculates from Master Task List.
B19: Master Task List | C19: Single source of truth — one row per task. Progress %, Duration, Remaining Days compute automatically from Status/dates.
B20: Completed Work | C20: Auto-filtered view of Completed tasks. Only 'Lessons Learned' is manually editable.
B21: Remaining Work | C21: Auto-filtered view of Not Started / Planning / Blocked tasks.
B22: Timeline | C22: Weekly Gantt chart. Bars are conditional-formatting driven from Start/End Date + Status/Priority; today's week is highlighted; milestones show as ◆.
B23: Milestones | C23: Key delivery milestones. Status and Progress are formula-derived from related module tasks.
B24: Risk Register | C24: Risk log with Severity = Probability × Impact (color-scaled).
B25: Team Progress | C25: Per-person workload and productivity, computed from Master Task List.
B26: Weekly Report | C26: Auto-summarized weekly snapshot: completed/started/overdue/critical, upcoming milestones, top risks.
B27: Roadmap | C27: Modules grouped by planned quarter with formula-driven progress bars.
B29: Assumptions & Notes
B30: • | C30: No real project data (tasks, dates, owners, budget) was supplied for Damanaty. All 90 tasks across the 30 requested modules are realistic illustrative content generated to demonstrate the template — replace with actual project data before use.
B31: • | C31: Budget Status on the Dashboard is a placeholder; no financial figures were provided.
B32: • | C32: Progress % is automatic: it is looked up from Status via the hidden Lists sheet. To change a task's progress, change its Status — do not type over the Progress % cell.
B33: • | C33: 'Pending' / Remaining Work = Not Started + Planning + Blocked statuses (Cancelled tasks are excluded from all counts and averages).
B34: • | C34: Formulas are pre-built with headroom through row 600 on Master Task List (and matching headroom on dependent sheets) so new tasks can be typed in directly — for growth beyond that, copy the last row's formula cells down.
B35: • | C35: Timeline granularity is weekly (Monday-start buckets) to keep the sheet a manageable size for a multi-year plan; exact day counts are shown in the Duration column of Master Task List and Timeline.
B36: • | C36: Dependency values are informational Task ID references (e.g. DMT-014) — they are not enforced by scheduling formulas.

Sheet Executive Dashboard
A1: ضماناتي (Damanaty) — Executive Dashboard
A3: =CONCATENATE("Report Date: ",TEXT(TODAY(),"yyyy-mm-dd")," | Project Health: ",_xlfn.IFS($C$18>0.15,"Red - At Risk",$C$18>0.05,"Yellow - Caution",TRUE(),"Green - On Track")) -> Report Date: 2026-07-26 | Project Health: Red - At Risk
A5: OVERALL PROGRESS | C5: COMPLETED TASKS | E5: IN PROGRESS | G5: PENDING TASKS | I5: OVERDUE TASKS | K5: CRITICAL TASKS
A6: =IFERROR(AVERAGE('Master Task List'!$J$2:$J$600),0) -> 0.34277778 | C6: =COUNTIF('Master Task List'!$I:$I,"Completed") -> 16 | E6: =COUNTIF('Master Task List'!$I:$I,"Design")+COUNTIF('Master Task List'!$I:$I,"Development")+COUNTIF('Master Task List'!$I:$I,"Testing")+COUNTIF('Master Task List'!$I:$I,"Review") -> 23 | G6: =COUNTIF('Master Task List'!$I:$I,"Not Started")+COUNTIF('Master Task List'!$I:$I,"Planning")+COUNTIF('Master Task List'!$I:$I,"Blocked") -> 50 | I6: =SUM('Master Task List'!$S$2:$S$600) -> 12 | K6: =COUNTIFS('Master Task List'!$F:$F,"Critical",'Master Task List'!$I:$I,"<>Completed",'Master Task List'!$I:$I,"<>Cancelled") -> 4
A10: UPCOMING MILESTONES (30D) | D10: PROJECT HEALTH | G10: BUDGET STATUS | J10: EXPECTED COMPLETION
A11: =COUNTIFS(Milestones!$C:$C,">="&TODAY(),Milestones!$C:$C,"<="&TODAY()+30,Milestones!$D:$D,"<>Completed") -> 1 | D11: =_xlfn.IFS($C$18>0.15,"🔴 At Risk",$C$18>0.05,"🟡 Caution",TRUE(),"🟢 On Track") -> 🔴 At Risk | G11: On Budget (placeholder) | J11: =MAX(Milestones!$C:$C) -> 46451
B18: OverdueRatio (helper): | C18: =IFERROR(SUM('Master Task List'!$S$2:$S$600)/COUNTIFS('Master Task List'!$I:$I,"<>Completed",'Master Task List'!$I:$I,"<>Cancelled",'Master Task List'!$A:$A,"<>"),0) -> 0.16216216
A20: =CONCATENATE("Project: ضماناتي (Damanaty) | Total Tasks: ",COUNTIF('Master Task List'!$A:$A,"DMT-*")," legend: blue text = editable input cells") -> Project: ضماناتي (Damanaty) | Total Tasks: 90 legend: blue text = editable input cells

Sheet Master Task List
A1: Task ID | B1: Module | C1: Feature | D1: Task | E1: Description | F1: Priority | G1: Owner | H1: Department | I1: Status | J1: Progress % | K1: Start Date | L1: End Date | M1: Actual Finish | N1: Duration (Days) | O1: Remaining Days | P1: Dependency | Q1: Risk Level | R1: Notes | S1: Overdue? | T1: CompletedRowKey | U1: RemainingRowKey | V1: ThisWeekCompletedKey | W1: CriticalOpenKey | X1: ThisWeekStartedKey | Y1: Upcoming7Key
A2: DMT-001 | B2: Project Planning | C2: خطة المشروع | D2: إعداد ميثاق المشروع | E2: صياغة ميثاق المشروع وتحديد الأهداف والنطاق والمخرجات الرئيسية | F2: Low | G2: سارة العتيبي | H2: PMO | I2: Completed | J2: =IF($A2="","",IFERROR(INDEX(Lists!$B$2:$B$10,MATCH($I2,Lists!$A$2:$A$10,0)),"")) -> 1 | K2: 46027 | L2: 46036 | M2: 46034 | N2: =IF($A2="","",$L2-$K2+1) -> 10 | O2: =IF($A2="","",IF(OR($I2="Completed",$I2="Cancelled"),0,$L2-TODAY())) -> 0 | Q2: Low | S2: =IF($A2="","",IF(AND($O2<0,$I2<>"Completed",$I2<>"Cancelled"),1,0)) -> 0 | T2: =IF($A2="","",IF($I2="Completed",ROW(),"")) -> 2 | U2: =IF($A2="","",IF(OR($I2="Not Started",$I2="Planning",$I2="Blocked"),ROW(),""))
A3: DMT-002 | B3: Project Planning | C3: خطة المشروع | D3: بناء خطة العمل الزمنية | E3: إعداد الجدول الزمني الرئيسي وتوزيع المراحل على الفرق | F3: Medium | G3: سارة العتيبي | H3: PMO | I3: Completed | J3: =IF($A3="","",IFERROR(INDEX(Lists!$B$2:$B$10,MATCH($I3,Lists!$A$2:$A$10,0)),"")) -> 1 | K3: 46037 | L3: 46046 | M3: 46049 | N3: =IF($A3="","",$L3-$K3+1) -> 10 | O3: =IF($A3="","",IF(OR($I3="Completed",$I3="Cancelled"),0,$L3-TODAY())) -> 0 | P3: DMT-001 | Q3: Low | S3: =IF($A3="","",IF(AND($O3<0,$I3<>"Completed",$I3<>"Cancelled"),1,0)) -> 0 | T3: =IF($A3="","",IF($I3="Completed",ROW(),"")) -> 3 | U3: =IF($A3="","",IF(OR($I3="Not Started",$I3="Planning",$I3="Blocked"),ROW(),""))
A4: DMT-003 | B4: Project Planning | C4: إدارة الموارد | D4: تخصيص فريق العمل | E4: تحديد أدوار الفريق ومسؤولياته وتخصيص الموارد لكل وحدة | F4: Medium | G4: سارة العتيبي | H4: PMO | I4: Completed | J4: =IF($A4="","",IFERROR(INDEX(Lists!$B$2:$B$10,MATCH($I4,Lists!$A$2:$A$10,0)),"")) -> 1 | K4: 46047 | L4: 46056 | M4: 46054 | N4: =IF($A4="","",$L4-$K4+1) -> 10 | O4: =IF($A4="","",IF(OR($I4="Completed",$I4="Cancelled"),0,$L4-TODAY())) -> 0 | P4: DMT-002 | Q4: Low | S4: =IF($A4="","",IF(AND($O4<0,$I4<>"Completed",$I4<>"Cancelled"),1,0)) -> 0 | T4: =IF($A4="","",IF($I4="Completed",ROW(),"")) -> 4 | U4: =IF($A4="","",IF(OR($I4="Not Started",$I4="Planning",$I4="Blocked"),ROW(),""))
A5: DMT-004 | B5: Business Analysis | C5: متطلبات العمل | D5: جمع متطلبات الضمانات | E5: مقابلة أصحاب المصلحة وتوثيق متطلبات إدارة الضمانات | F5: Low | G5: محمد القحطاني | H5: Business Analysis | I5: Completed | J5: =IF($A5="","",IFERROR(INDEX(Lists!$B$2:$B$10,MATCH($I5,Lists!$A$2:$A$10,0)),"")) -> 1 | K5: 46042 | L5: 46056 | M5: 46054 | N5: =IF($A5="","",$L5-$K5+1) -> 15 | O5: =IF($A5="","",IF(OR($I5="Completed",$I5="Cancelled"),0,$L5-TODAY())) -> 0 | P5: DMT-001 | Q5: Low | S5: =IF($A5="","",IF(AND($O5<0,$I5<>"Completed",$I5<>"Cancelled"),1,0)) -> 0 | T5: =IF($A5="","",IF($I5="Completed",ROW(),"")) -> 5 | U5: =IF($A5="","",IF(OR($I5="Not Started",$I5="Planning",$I5="Blocked"),ROW(),""))
A6: DMT-005 | B6: Business Analysis | C6: متطلبات العمل | D6: تحليل نموذج العمل | E6: دراسة نموذج الإيرادات والمستخدمين المستهدفين للتطبيق | F6: Medium | G6: محمد القحطاني | H6: Business Analysis | I6: Completed | J6: =IF($A6="","",IFERROR(INDEX(Lists!$B$2:$B$10,MATCH($I6,Lists!$A$2:$A$10,0)),"")) -> 1 | K6: 46057 | L6: 46072 | M6: 46075 | N6: =IF($A6="","",$L6-$K6+1) -> 16 | O6: =IF($A6="","",IF(OR($I6="Completed",$I6="Cancelled"),0,$L6-TODAY())) -> 0 | P6: DMT-004 | Q6: Low | S6: =IF($A6="","",IF(AND($O6<0,$I6<>"Completed",$I6<>"Cancelled"),1,0)) -> 0 | T6: =IF($A6="","",IF($I6="Completed",ROW(),"")) -> 6 | U6: =IF($A6="","",IF(OR($I6="Not Started",$I6="Planning",$I6="Blocked"),ROW(),""))
A7: DMT-006 | B7: Business Analysis | C7: توثيق المتطلبات | D7: إعداد وثيقة المتطلبات (BRD) | E7: توثيق متطلبات العمل الشاملة ومراجعتها مع الإدارة | F7: Medium | G7: محمد القحطاني | H7: Business Analysis | I7: Completed | J7: =IF($A7="","",IFERROR(INDEX(Lists!$B$2:$B$10,MATCH($I7,Lists!$A$2:$A$10,0)),"")) -> 1 | K7: 46073 | L7: 46087 | M7: 46085 | N7: =IF($A7="","",$L7-$K7+1) -> 15 | O7: =IF($A7="","",IF(OR($I7="Completed",$I7="Cancelled"),0,$L7-TODAY())) -> 0 | P7: DMT-005 | Q7: Low | S7: =IF($A7="","",IF(AND($O7<0,$I7<>"Completed",$I7<>"Cancelled"),1,0)) -> 0 | T7: =IF($A7="","",IF($I7="Completed",ROW(),"")) -> 7 | U7: =IF($A7="","",IF(OR($I7="Not Started",$I7="Planning",$I7="Blocked"),ROW(),""))
A8: DMT-007 | B8: UI/UX Design | C8: تجربة المستخدم | D8: بناء خرائط تدفق المستخدم | E8: تصميم مسارات المستخدم الرئيسية داخل التطبيق والموقع | F8: Medium | G8: نورة الدوسري | H8: Design | I8: Completed | J8: =IF($A8="","",IFERROR(INDEX(Lists!$B$2:$B$10,MATCH($I8,Lists!$A$2:$A$10,0)),"")) -> 1 | K8: 46073 | L8: 46092 | M8: 46090 | N8: =IF($A8="","",$L8-$K8+1) -> 20 | O8: =IF($A8="","",IF(OR($I8="Completed",$I8="Cancelled"),0,$L8-TODAY())) -> 0 | P8: DMT-004 | Q8: Low | S8: =IF($A8="","",IF(AND($O8<0,$I8<>"Completed",$I8<>"Cancelled"),1,0)) -> 0 | T8: =IF($A8="","",IF($I8="Completed",ROW(),"")) -> 8 | U8: =IF($A8="","",IF(OR($I8="Not Started",$I8="Planning",$I8="Blocked"),ROW(),""))
A9: DMT-008 | B9: UI/UX Design | C9: واجهة المستخدم | D9: تصميم نظام التصميم (Design System) | E9: بناء مكتبة المكونات والألوان والخطوط الموحدة | F9: Medium | G9: نورة الدوسري | H9: Design | I9: Completed | J9: =IF($A9="","",IFERROR(INDEX(Lists!$B$2:$B$10,MATCH($I9,Lists!$A$2:$A$10,0)),"")) -> 1 | K9: 46093 | L9: 46112 | M9: 46115 | N9: =IF($A9="","",$L9-$K9+1) -> 20 | O9: =IF($A9="","",IF(OR($I9="Completed",$I9="Cancelled"),0,$L9-TODAY())) -> 0 | P9: DMT-007 | Q9: Low | S9: =IF($A9="","",IF(AND($O9<0,$I9<>"Completed",$I9<>"Cancelled"),1,0)) -> 0 | T9: =IF($A9="","",IF($I9="Completed",ROW(),"")) -> 9 | U9: =IF($A9="","",IF(OR($I9="Not Started",$I9="Planning",$I9="Blocked"),ROW(),""))
A10: DMT-009 | B10: UI/UX Design | C10: النماذج الأولية | D10: تصميم النماذج التفاعلية (Prototype) | E10: إعداد نماذج Figma قابلة للاختبار مع المستخدمين | F10: Medium | G10: نورة الدوسري | H10: Design | I10: Completed | J10: =IF($A10="","",IFERROR(INDEX(Lists!$B$2:$B$10,MATCH($I10,Lists!$A$2:$A$10,0)),"")) -> 1 | K10: 46113 | L10: 46132 | M10: 46130 | N10: =IF($A10="","",$L10-$K10+1) -> 20 | O10: =IF($A10="","",IF(OR($I10="Completed",$I10="Cancelled"),0,$L10-TODAY())) -> 0 | P10: DMT-008 | Q10: Low | S10: =IF($A10="","",IF(AND($O10<0,$I10<>"Completed",$I10<>"Cancelled"),1,0)) -> 0 | T10: =IF($A10="","",IF($I10="Completed",ROW(),"")) -> 10 | U10: =IF($A10="","",IF(OR($I10="Not Started",$I10="Planning",$I10="Blocked"),ROW(),""))
A11: DMT-010 | B11: Branding | C11: الهوية البصرية | D11: تصميم الشعار وتصميم الهوية | E11: تصميم شعار ضماناتي ودليل الهوية البصرية الكامل | F11: Low | G11: عبدالله الشمري | H11: Design | I11: Completed | J11: =IF($A11="","",IFERROR(INDEX(Lists!$B$2:$B$10,MATCH($I11,Lists!$A$2:$A$10,0)),"")) -> 1 | K11: 46073 | L11: 46087 | M11: 46085 | N11: =IF($A11="","",$L11-$K11+1) -> 15 | O11: =IF($A11="","",IF(OR($I11="Completed",$I11="Cancelled"),0,$L11-TODAY())) -> 0 | P11: DMT-004 | Q11: Low | S11: =IF($A11="","",IF(AND($O11<0,$I11<>"Completed",$I11<>"Cancelled"),1,0)) -> 0 | T11: =IF($A11="","",IF($I11="Completed",ROW(),"")) -> 11 | U11: =IF($A11="","",IF(OR($I11="Not Started",$I11="Planning",$I11="Blocked"),ROW(),""))
A12: DMT-011 | B12: Branding | C12: الهوية البصرية | D12: تطوير دليل العلامة التجارية | E12: إعداد دليل استخدام الشعار والألوان لجميع المنصات | F12: Medium | G12: عبدالله الشمري | H12: Design | I12: Completed | J12: =IF($A12="","",IFERROR(INDEX(Lists!$B$2:$B$10,MATCH($I12,Lists!$A$2:$A$10,0)),"")) -> 1 | K12: 46088 | L12: 46102 | M12: 46105 | N12: =IF($A12="","",$L12-$K12+1) -> 15 | O12: =IF($A12="","",IF(OR($I12="Completed",$I12="Cancelled"),0,$L12-TODAY())) -> 0 | P12: DMT-010 | Q12: Low | S12: =IF($A12="","",IF(AND($O12<0,$I12<>"Completed",$I12<>"Cancelled"),1,0)) -> 0 | T12: =IF($A12="","",IF($I12="Completed",ROW(),"")) -> 12 | U12: =IF($A12="","",IF(OR($I12="Not Started",$I12="Planning",$I12="Blocked"),ROW(),""))
A13: DMT-012 | B13: Branding | C13: التسويق | D13: تصميم مواد تسويقية أولية | E13: تصميم القوالب التسويقية لوسائل التواصل الاجتماعي | F13: Medium | G13: عبدالله الشمري | H13: Design | I13: Completed | J13: =IF($A13="","",IFERROR(INDEX(Lists!$B$2:$B$10,MATCH($I13,Lists!$A$2:$A$10,0)),"")) -> 1 | K13: 46103 | L13: 46117 | M13: 46115 | N13: =IF($A13="","",$L13-$K13+1) -> 15 | O13: =IF($A13="","",IF(OR($I13="Completed",$I13="Cancelled"),0,$L13-TODAY())) -> 0 | P13: DMT-011 | Q13: Low | S13: =IF($A13="","",IF(AND($O13<0,$I13<>"Completed",$I13<>"Cancelled"),1,0)) -> 0 | T13: =IF($A13="","",IF($I13="Completed",ROW(),"")) -> 13 | U13: =IF($A13="","",IF(OR($I13="Not Started",$I13="Planning",$I13="Blocked"),ROW(),""))
A14: DMT-013 | B14: Mobile App | C14: تطبيق الجوال | D14: إعداد بنية تطبيق iOS/Android | E14: إعداد المشروع الأساسي والبنية المعمارية للتطبيق | F14: Medium | G14: فيصل المطيري | H14: Engineering | I14: Testing | J14: =IF($A14="","",IFERROR(INDEX(Lists!$B$2:$B$10,MATCH($I14,Lists!$A$2:$A$10,0)),"")) -> 0.75 | K14: 46118 | L14: 46168 | N14: =IF($A14="","",$L14-$K14+1) -> 51 | O14: =IF($A14="","",IF(OR($I14="Completed",$I14="Cancelled"),0,$L14-TODAY())) -> -61 | P14: DMT-007 | Q14: Medium | S14: =IF($A14="","",IF(AND($O14<0,$I14<>"Completed",$I14<>"Cancelled"),1,0)) -> 1 | T14: =IF($A14="","",IF($I14="Completed",ROW(),"")) | U14: =IF($A14="","",IF(OR($I14="Not Started",$I14="Planning",$I14="Blocked"),ROW(),""))
A15: DMT-014 | B15: Mobile App | C15: تطبيق الجوال | D15: تطوير الشاشات الرئيسية | E15: بناء شاشات لوحة التحكم والملف الشخصي والإشعارات | F15: Medium | G15: فيصل المطيري | H15: Engineering | I15: Testing | J15: =IF($A15="","",IFERROR(INDEX(Lists!$B$2:$B$10,MATCH($I15,Lists!$A$2:$A$10,0)),"")) -> 0.75 | K15: 46169 | L15: 46218 | N15: =IF($A15="","",$L15-$K15+1) -> 50 | O15: =IF($A15="","",IF(OR($I15="Completed",$I15="Cancelled"),0,$L15-TODAY())) -> -11 | P15: DMT-013 | Q15: Medium | S15: =IF($A15="","",IF(AND($O15<0,$I15<>"Completed",$I15<>"Cancelled"),1,0)) -> 1 | T15: =IF($A15="","",IF($I15="Completed",ROW(),"")) | U15: =IF($A15="","",IF(OR($I15="Not Started",$I15="Planning",$I15="Blocked"),ROW(),""))
A16: DMT-015 | B16: Mobile App | C16: تطبيق الجوال | D16: دمج بوابات الدفع | E16: ربط تطبيق الجوال ببوابات الدفع المحلية | F16: Medium | G16: فيصل المطيري | H16: Engineering | I16: Development | J16: =IF($A16="","",IFERROR(INDEX(Lists!$B$2:$B$10,MATCH($I16,Lists!$A$2:$A$10,0)),"")) -> 0.55 | K16: 46219 | L16: 46269 | N16: =IF($A16="","",$L16-$K16+1) -> 51 | O16: =IF($A16="","",IF(OR($I16="Completed",$I16="Cancelled"),0,$L16-TODAY())) -> 40 | P16: DMT-014 | Q16: Medium | S16: =IF($A16="","",IF(AND($O16<0,$I16<>"Completed",$I16<>"Cancelled"),1,0)) -> 0 | T16: =IF($A16="","",IF($I16="Completed",ROW(),"")) | U16: =IF($A16="","",IF(OR($I16="Not Started",$I16="Planning",$I16="Blocked"),ROW(),""))
A17: DMT-016 | B17: Web Dashboard | C17: لوحة الويب | D17: إعداد بنية الواجهة الأمامية | E17: إعداد مشروع React وبنية المكونات المشتركة | F17: Medium | G17: ريم الحربي | H17: Engineering | I17: Testing | J17: =IF($A17="","",IFERROR(INDEX(Lists!$B$2:$B$10,MATCH($I17,Lists!$A$2:$A$10,0)),"")) -> 0.75 | K17: 46133 | L17: 46178 | N17: =IF($A17="","",$L17-$K17+1) -> 46 | O17: =IF($A17="","",IF(OR($I17="Completed",$I17="Cancelled"),0,$L17-TODAY())) -> -51 | P17: DMT-007 | Q17: Medium | S17: =IF($A17="","",IF(AND($O17<0,$I17<>"Completed",$I17<>"Cancelled"),1,0)) -> 1 | T17: =IF($A17="","",IF($I17="Completed",ROW(),"")) | U17: =IF($A17="","",IF(OR($I17="Not Started",$I17="Planning",$I17="Blocked"),ROW(),""))
A18: DMT-017 | B18: Web Dashboard | C18: لوحة الويب | D18: تطوير لوحة التحكم الرئيسية | E18: بناء الصفحة الرئيسية للوحة التحكم وعرض الإحصائيات | F18: Medium | G18: ريم الحربي | H18: Engineering | I18: Testing | J18: =IF($A18="","",IFERROR(INDEX(Lists!$B$2:$B$10,MATCH($I18,Lists!$A$2:$A$10,0)),"")) -> 0.75 | K18: 46179 | L18: 46223 | N18: =IF($A18="","",$L18-$K18+1) -> 45 | O18: =IF($A18="","",IF(OR($I18="Completed",$I18="Cancelled"),0,$L18-TODAY())) -> -6 | P18: DMT-016 | Q18: Medium | S18: =IF($A18="","",IF(AND($O18<0,$I18<>"Completed",$I18<>"Cancelled"),1,0)) -> 1 | T18: =IF($A18="","",IF($I18="Completed",ROW(),"")) | U18: =IF($A18="","",IF(OR($I18="Not Started",$I18="Planning",$I18="Blocked"),ROW(),""))
A19: DMT-018 | B19: Web Dashboard | C19: لوحة الويب | D19: تطوير صفحات إدارة الضمانات | E19: بناء واجهات عرض وتعديل الضمانات على الويب | F19: Medium | G19: ريم الحربي | H19: Engineering | I19: Development | J19: =IF($A19="","",IFERROR(INDEX(Lists!$B$2:$B$10,MATCH($I19,Lists!$A$2:$A$10,0)),"")) -> 0.55 | K19: 46224 | L19: 46269 | N19: =IF($A19="","",$L19-$K19+1) -> 46 | O19: =IF($A19="","",IF(OR($I19="Completed",$I19="Cancelled"),0,$L19-TODAY())) -> 40 | P19: DMT-017 | Q19: Medium | S19: =IF($A19="","",IF(AND($O19<0,$I19<>"Completed",$I19<>"Cancelled"),1,0)) -> 0 | T19: =IF($A19="","",IF($I19="Completed",ROW(),"")) | U19: =IF($A19="","",IF(OR($I19="Not Started",$I19="Planning",$I19="Blocked"),ROW(),""))
A20: DMT-019 | B20: Authentication | C20: المصادقة | D20: تطوير تسجيل الدخول وكلمة المرور | E20: بناء نظام تسجيل الدخول الآمن مع التحقق من كلمة المرور | F20: High | G20: خالد الغامدي | H20: Engineering | I20: Completed | J20: =IF($A20="","",IFERROR(INDEX(Lists!$B$2:$B$10,MATCH($I20,Lists!$A$2:$A$10,0)),"")) -> 1 | K20: 46118 | L20: 46137 | M20: 46135 | N20: =IF($A20="","",$L20-$K20+1) -> 20 | O20: =IF($A20="","",IF(OR($I20="Completed",$I20="Cancelled"),0,$L20-TODAY())) -> 0 | P20: DMT-016 | Q20: Low | S20: =IF($A20="","",IF(AND($O20<0,$I20<>"Completed",$I20<>"Cancelled"),1,0)) -> 0 | T20: =IF($A20="","",IF($I20="Completed",ROW(),"")) -> 20 | U20: =IF($A20="","",IF(OR($I20="Not Started",$I20="Planning",$I20="Blocked"),ROW(),""))
A21: DMT-020 | B21: Authentication | C21: المصادقة | D21: دمج المصادقة الثنائية (OTP) | E21: إضافة التحقق عبر رسائل SMS ورمز OTP | F21: High | G21: خالد الغامدي | H21: Engineering | I21: Completed | J21: =IF($A21="","",IFERROR(INDEX(Lists!$B$2:$B$10,MATCH($I21,Lists!$A$2:$A$10,0)),"")) -> 1 | K21: 46138 | L21: 46158 | M21: 46161 | N21: =IF($A21="","",$L21-$K21+1) -> 21 | O21: =IF($A21="","",IF(OR($I21="Completed",$I21="Cancelled"),0,$L21-TODAY())) -> 0 | P21: DMT-019 | Q21: Low | S21: =IF($A21="","",IF(AND($O21<0,$I21<>"Completed",$I21<>"Cancelled"),1,0)) -> 0 | T21: =IF($A21="","",IF($I21="Completed",ROW(),"")) -> 21 | U21: =IF($A21="","",IF(OR($I21="Not Started",$I21="Planning",$I21="Blocked"),ROW(),""))
A22: DMT-021 | B22: Authentication | C22: المصادقة | D22: دمج تسجيل الدخول الموحد (SSO/نفاذ) | E22: ربط النظام مع منصة نفاذ الوطنية للهوية الرقمية | F22: High | G22: خالد الغامدي | H22: Engineering | I22: Completed | J22: =IF($A22="","",IFERROR(INDEX(Lists!$B$2:$B$10,MATCH($I22,Lists!$A$2:$A$10,0)),"")) -> 1 | K22: 46159 | L22: 46178 | M22: 46176 | N22: =IF($A22="","",$L22-$K22+1) -> 20 | O22: =IF($A22="","",IF(OR($I22="Completed",$I22="Cancelled"),0,$L22-TODAY())) -> 0 | P22: DMT-020 | Q22: Low | S22: =IF($A22="","",IF(AND($O22<0,$I22<>"Completed",$I22<>"Cancelled"),1,0)) -> 0 | T22: =IF($A22="","",IF($I22="Completed",ROW(),"")) -> 22 | U22: =IF($A22="","",IF(OR($I22="Not Started",$I22="Planning",$I22="Blocked"),ROW(),""))
A23: DMT-022 | B23: User Management | C23: إدارة المستخدمين | D23: بناء نظام الأدوار والصلاحيات | E23: تصميم نظام RBAC لإدارة صلاحيات المستخدمين | F23: Medium | G23: لمياء العنزي | H23: Engineering | I23: Completed | J23: =IF($A23="","",IFERROR(INDEX(Lists!$B$2:$B$10,MATCH($I23,Lists!$A$2:$A$10,0)),"")) -> 1 | K23: 46149 | L23: 46173 | M23: 46171 | N23: =IF($A23="","",$L23-$K23+1) -> 25 | O23: =IF($A23="","",IF(OR($I23="Completed",$I23="Cancelled"),0,$L23-TODAY())) -> 0 | P23: DMT-019 | Q23: Low | S23: =IF($A23="","",IF(AND($O23<0,$I23<>"Completed",$I23<>"Cancelled"),1,0)) -> 0 | T23: =IF($A23="","",IF($I23="Completed",ROW(),"")) -> 23 | U23: =IF($A23="","",IF(OR($I23="Not Started",$I23="Planning",$I23="Blocked"),ROW(),""))
A24: DMT-023 | B24: User Management | C24: إدارة المستخدمين | D24: تطوير الملف الشخصي للمستخدم | E24: بناء صفحة الملف الشخصي وتحديث البيانات | F24: Medium | G24: لمياء العنزي | H24: Engineering | I24: Review | J24: =IF($A24="","",IFERROR(INDEX(Lists!$B$2:$B$10,MATCH($I24,Lists!$A$2:$A$10,0)),"")) -> 0.9 | K24: 46174 | L24: 46199 | N24: =IF($A24="","",$L24-$K24+1) -> 26 | O24: =IF($A24="","",IF(OR($I24="Completed",$I24="Cancelled"),0,$L24-TODAY())) -> -30 | P24: DMT-022 | Q24: Medium | S24: =IF($A24="","",IF(AND($O24<0,$I24<>"Completed",$I24<>"Cancelled"),1,0)) -> 1 | T24: =IF($A24="","",IF($I24="Completed",ROW(),"")) | U24: =IF($A24="","",IF(OR($I24="Not Started",$I24="Planning",$I24="Blocked"),ROW(),""))
A25: DMT-024 | B25: User Management | C25: إدارة المستخدمين | D25: إدارة حسابات الشركات | E25: دعم الحسابات المؤسسية متعددة المستخدمين | F25: Medium | G25: لمياء العنزي | H25: Engineering | I25: Testing | J25: =IF($A25="","",IFERROR(INDEX(Lists!$B$2:$B$10,MATCH($I25,Lists!$A$2:$A$10,0)),"")) -> 0.75 | K25: 46200 | L25: 46224 | N25: =IF($A25="","",$L25-$K25+1) -> 25 | O25: =IF($A25="","",IF(OR($I25="Completed",$I25="Cancelled"),0,$L25-TODAY())) -> -5 | P25: DMT-023 | Q25: Medium | S25: =IF($A25="","",IF(AND($O25<0,$I25<>"Completed",$I25<>"Cancelled"),1,0)) -> 1 | T25: =IF($A25="","",IF($I25="Completed",ROW(),"")) | U25: =IF($A25="","",IF(OR($I25="Not Started",$I25="Planning",$I25="Blocked"),ROW(),""))
A26: DMT-025 | B26: Guarantee Management | C26: إدارة الضمانات | D26: تصميم قاعدة بيانات الضمانات | E26: تصميم نموذج البيانات الخاص بأنواع الضمانات وحالاتها | F26: Critical | G26: خالد الغامدي | H26: Engineering | I26: Testing | J26: =IF($A26="","",IFERROR(INDEX(Lists!$B$2:$B$10,MATCH($I26,Lists!$A$2:$A$10,0)),"")) -> 0.75 | K26: 46164 | L26: 46193 | N26: =IF($A26="","",$L26-$K26+1) -> 30 | O26: =IF($A26="","",IF(OR($I26="Completed",$I26="Cancelled"),0,$L26-TODAY())) -> -36 | P26: DMT-022 | Q26: Critical | S26: =IF($A26="","",IF(AND($O26<0,$I26<>"Completed",$I26<>"Cancelled"),1,0)) -> 1 | T26: =IF($A26="","",IF($I26="Completed",ROW(),"")) | U26: =IF($A26="","",IF(OR($I26="Not Started",$I26="Planning",$I26="Blocked"),ROW(),""))
A27: DMT-026 | B27: Guarantee Management | C27: إدارة الضمانات | D27: تطوير محرك إدارة دورة حياة الضمان | E27: بناء منطق الأعمال لحالات الضمان من الإنشاء إلى الإغلاق | F27: High | G27: خالد الغامدي | H27: Engineering | I27: Testing | J27: =IF($A27="","",IFERROR(INDEX(Lists!$B$2:$B$10,MATCH($I27,Lists!$A$2:$A$10,0)),"")) -> 0.75 | K27: 46194 | L27: 46224 | N27: =IF($A27="","",$L27-$K27+1) -> 31 | O27: =IF($A27="","",IF(OR($I27="Completed",$I27="Cancelled"),0,$L27-TODAY())) -> -5 | P27: DMT-025 | Q27: Critical | S27: =IF($A27="","",IF(AND($O27<0,$I27<>"Completed",$I27<>"Cancelled"),1,0)) -> 1 | T27: =IF($A27="","",IF($I27="Completed",ROW(),"")) | U27: =IF($A27="","",IF(OR($I27="Not Started",$I27="Planning",$I27="Blocked"),ROW(),""))
A28: DMT-027 | B28: Guarantee Management | C28: إدارة الضمانات | D28: تطوير واجهة إدارة الضمانات للمشرفين | E28: بناء أدوات إدارية لمراجعة وتعديل الضمانات | F28: High | G28: خالد الغامدي | H28: Engineering | I28: Development | J28: =IF($A28="","",IFERROR(INDEX(Lists!$B$2:$B$10,MATCH($I28,Lists!$A$2:$A$10,0)),"")) -> 0.55 | K28: 46225 | L28: 46254 | N28: =IF($A28="","",$L28-$K28+1) -> 30 | O28: =IF($A28="","",IF(OR($I28="Completed",$I28="Cancelled"),0,$L28-TODAY())) -> 25 | P28: DMT-026 | Q28: Critical | S28: =IF($A28="","",IF(AND($O28<0,$I28<>"Completed",$I28<>"Cancelled"),1,0)) -> 0 | T28: =IF($A28="","",IF($I28="Completed",ROW(),"")) | U28: =IF($A28="","",IF(OR($I28="Not Started",$I28="Planning",$I28="Blocked"),ROW(),""))
A29: DMT-028 | B29: Guarantee Registration | C29: تسجيل الضمانات | D29: بناء نموذج تسجيل الضمان | E29: تطوير نموذج تسجيل ضمان جديد مع التحقق من الحقول | F29: Critical | G29: لمياء العنزي | H29: Engineering | I29: Development | J29: =IF($A29="","",IFERROR(INDEX(Lists!$B$2:$B$10,MATCH($I29,Lists!$A$2:$A$10,0)),"")) -> 0.55 | K29: 46194 | L29: 46223 | N29: =IF($A29="","",$L29-$K29+1) -> 30 | O29: =IF($A29="","",IF(OR($I29="Completed",$I29="Cancelled"),0,$L29-TODAY())) -> -6 | P29: DMT-025 | Q29: Critical | S29: =IF($A29="","",IF(AND($O29<0,$I29<>"Completed",$I29<>"Cancelled"),1,0)) -> 1 | T29: =IF($A29="","",IF($I29="Completed",ROW(),"")) | U29: =IF($A29="","",IF(OR($I29="Not Started",$I29="Planning",$I29="Blocked"),ROW(),""))
A30: DMT-029 | B30: Guarantee Registration | C30: تسجيل الضمانات | D30: رفع وإدارة المستندات | E30: إضافة خاصية رفع صور وفواتير الضمان | F30: High | G30: لمياء العنزي | H30: Engineering | I30: Design | J30: =IF($A30="","",IFERROR(INDEX(Lists!$B$2:$B$10,MATCH($I30,Lists!$A$2:$A$10,0)),"")) -> 0.3 | K30: 46224 | L30: 46254 | N30: =IF($A30="","",$L30-$K30+1) -> 31 | O30: =IF($A30="","",IF(OR($I30="Completed",$I30="Cancelled"),0,$L30-TODAY())) -> 25 | P30: DMT-028 | Q30: Critical | S30: =IF($A30="","",IF(AND($O30<0,$I30<>"Completed",$I30<>"Cancelled"),1,0)) -> 0 | T30: =IF($A30="","",IF($I30="Completed",ROW(),"")) | U30: =IF($A30="","",IF(OR($I30="Not Started",$I30="Planning",$I30="Blocked"),ROW(),""))
A31: DMT-030 | B31: Guarantee Registration | C31: تسجيل الضمانات | D31: دمج بيانات المتاجر والموردين | E31: ربط نموذج التسجيل بقاعدة بيانات المتاجر المعتمدة | F31: High | G31: لمياء العنزي | H31: Engineering | I31: Planning | J31: =IF($A31="","",IFERROR(INDEX(Lists!$B$2:$B$10,MATCH($I31,Lists!$A$2:$A$10,0)),"")) -> 0.15 | K31: 46255 | L31: 46284 | N31: =IF($A31="","",$L31-$K31+1) -> 30 | O31: =IF($A31="","",IF(OR($I31="Completed",$I31="Cancelled"),0,$L31-TODAY())) -> 55 | P31: DMT-029 | Q31: Critical | S31: =IF($A31="","",IF(AND($O31<0,$I31<>"Completed",$I31<>"Cancelled"),1,0)) -> 0 | T31: =IF($A31="","",IF($I31="Completed",ROW(),"")) | U31: =IF($A31="","",IF(OR($I31="Not Started",$I31="Planning",$I31="Blocked"),ROW(),"")) -> 31
A32: DMT-031 | B32: Guarantee Verification | C32: التحقق من الضمانات | D32: بناء خدمة التحقق الفوري | E32: تطوير خدمة API للتحقق من صلاحية الضمان لحظيًا | F32: Critical | G32: خالد الغامدي | H32: Engineering | I32: Planning | J32: =IF($A32="","",IFERROR(INDEX(Lists!$B$2:$B$10,MATCH($I32,Lists!$A$2:$A$10,0)),"")) -> 0.15 | K32: 46225 | L32: 46254 | N32: =IF($A32="","",$L32-$K32+1) -> 30 | O32: =IF($A32="","",IF(OR($I32="Completed",$I32="Cancelled"),0,$L32-TODAY())) -> 25 | P32: DMT-028 | Q32: Critical | S32: =IF($A32="","",IF(AND($O32<0,$I32<>"Completed",$I32<>"Cancelled"),1,0)) -> 0 | T32: =IF($A32="","",IF($I32="Completed",ROW(),"")) | U32: =IF($A32="","",IF(OR($I32="Not Started",$I32="Planning",$I32="Blocked"),ROW(),"")) -> 32
A33: DMT-032 | B33: Guarantee Verification | C33: التحقق من الضمانات | D33: دمج التحقق مع أنظمة الموردين | E33: ربط النظام مع أنظمة الموردين الخارجية للتحقق من الفاتورة | F33: High | G33: خالد الغامدي | H33: Engineering | I33: Blocked | J33: =IF($A33="","",IFERROR(INDEX(Lists!$B$2:$B$10,MATCH($I33,Lists!$A$2:$A$10,0)),"")) -> 0.4 | K33: 46255 | L33: 46285 | N33: =IF($A33="","",$L33-$K33+1) -> 31 | O33: =IF($A33="","",IF(OR($I33="Completed",$I33="Cancelled"),0,$L33-TODAY())) -> 56 | P33: DMT-031 | Q33: Critical | R33: متوقف: بانتظار توقيع اتفاقية تكامل مع مزود API الخارجي | S33: =IF($A33="","",IF(AND($O33<0,$I33<>"Completed",$I33<>"Cancelled"),1,0)) -> 0 | T33: =IF($A33="","",IF($I33="Completed",ROW(),"")) | U33: =IF($A33="","",IF(OR($I33="Not Started",$I33="Planning",$I33="Blocked"),ROW(),"")) -> 33
A34: DMT-033 | B34: Guarantee Verification | C34: التحقق من الضمانات | D34: بناء سجل تدقيق التحقق | E34: تسجيل كل عمليات التحقق لأغراض التدقيق والمراجعة | F34: High | G34: خالد الغامدي | H34: Engineering | I34: Not Started | J34: =IF($A34="","",IFERROR(INDEX(Lists!$B$2:$B$10,MATCH($I34,Lists!$A$2:$A$10,0)),"")) -> 0 | K34: 46286 | L34: 46315 | N34: =IF($A34="","",$L34-$K34+1) -> 30 | O34: =IF($A34="","",IF(OR($I34="Completed",$I34="Cancelled"),0,$L34-TODAY())) -> 86 | P34: DMT-032 | Q34: Critical | S34: =IF($A34="","",IF(AND($O34<0,$I34<>"Completed",$I34<>"Cancelled"),1,0)) -> 0 | T34: =IF($A34="","",IF($I34="Completed",ROW(),"")) | U34: =IF($A34="","",IF(OR($I34="Not Started",$I34="Planning",$I34="Blocked"),ROW(),"")) -> 34
A35: DMT-034 | B35: QR Code System | C35: رمز الاستجابة السريعة | D35: توليد رمز QR لكل ضمان | E35: بناء خدمة توليد رمز QR فريد لكل ضمان مسجل | F35: Medium | G35: فيصل المطيري | H35: Engineering | I35: Not Started | J35: =IF($A35="","",IFERROR(INDEX(Lists!$B$2:$B$10,MATCH($I35,Lists!$A$2:$A$10,0)),"")) -> 0 | K35: 46240 | L35: 46259 | N35: =IF($A35="","",$L35-$K35+1) -> 20 | O35: =IF($A35="","",IF(OR($I35="Completed",$I35="Cancelled"),0,$L35-TODAY())) -> 30 | P35: DMT-028 | Q35: Medium | S35: =IF($A35="","",IF(AND($O35<0,$I35<>"Completed",$I35<>"Cancelled"),1,0)) -> 0 | T35: =IF($A35="","",IF($I35="Completed",ROW(),"")) | U35: =IF($A35="","",IF(OR($I35="Not Started",$I35="Planning",$I35="Blocked"),ROW(),"")) -> 35
A36: DMT-035 | B36: QR Code System | C36: رمز الاستجابة السريعة | D36: تطوير ماسح QR داخل التطبيق | E36: إضافة كاميرا لمسح رمز QR والتحقق الفوري | F36: Medium | G36: فيصل المطيري | H36: Engineering | I36: Not Started | J36: =IF($A36="","",IFERROR(INDEX(Lists!$B$2:$B$10,MATCH($I36,Lists!$A$2:$A$10,0)),"")) -> 0 | K36: 46260 | L36: 46280 | N36: =IF($A36="","",$L36-$K36+1) -> 21 | O36: =IF($A36="","",IF(OR($I36="Completed",$I36="Cancelled"),0,$L36-TODAY())) -> 51 | P36: DMT-034 | Q36: Medium | S36: =IF($A36="","",IF(AND($O36<0,$I36<>"Completed",$I36<>"Cancelled"),1,0)) -> 0 | T36: =IF($A36="","",IF($I36="Completed",ROW(),"")) | U36: =IF($A36="","",IF(OR($I36="Not Started",$I36="Planning",$I36="Blocked"),ROW(),"")) -> 36
A37: DMT-036 | B37: QR Code System | C37: رمز الاستجابة السريعة | D37: طباعة وتوزيع ملصقات QR | E37: تصميم آلية طباعة ملصقات QR للمتاجر الشريكة | F37: Medium | G37: فيصل المطيري | H37: Engineering | I37: Not Started | J37: =IF($A37="","",IFERROR(INDEX(Lists!$B$2:$B$10,MATCH($I37,Lists!$A$2:$A$10,0)),"")) -> 0 | K37: 46281 | L37: 46300 | N37: =IF($A37="","",$L37-$K37+1) -> 20 | O37: =IF($A37="","",IF(OR($I37="Completed",$I37="Cancelled"),0,$L37-TODAY())) -> 71 | P37: DMT-035 | Q37: Medium | S37: =IF($A37="","",IF(AND($O37<0,$I37<>"Completed",$I37<>"Cancelled"),1,0)) -> 0 | T37: =IF($A37="","",IF($I37="Completed",ROW(),"")) | U37: =IF($A37="","",IF(OR($I37="Not Started",$I37="Planning",$I37="Blocked"),ROW(),"")) -> 37
A38: DMT-037 | B38: Notifications | C38: الإشعارات | D38: بناء محرك الإشعارات الفورية | E38: تطوير خدمة Push Notifications للتطبيق | F38: Low | G38: لمياء العنزي | H38: Engineering | I38: Not Started | J38: =IF($A38="","",IFERROR(INDEX(Lists!$B$2:$B$10,MATCH($I38,Lists!$A$2:$A$10,0)),"")) -> 0 | K38: 46255 | L38: 46274 | N38: =IF($A38="","",$L38-$K38+1) -> 20 | O38: =IF($A38="","",IF(OR($I38="Completed",$I38="Cancelled"),0,$L38-TODAY())) -> 45 | P38: DMT-022 | Q38: Low | S38: =IF($A38="","",IF(AND($O38<0,$I38<>"Completed",$I38<>"Cancelled"),1,0)) -> 0 | T38: =IF($A38="","",IF($I38="Completed",ROW(),"")) | U38: =IF($A38="","",IF(OR($I38="Not Started",$I38="Planning",$I38="Blocked"),ROW(),"")) -> 38
A39: DMT-038 | B39: Notifications | C39: الإشعارات | D39: إشعارات انتهاء صلاحية الضمان | E39: بناء تنبيهات تلقائية قبل انتهاء مدة الضمان | F39: Medium | G39: لمياء العنزي | H39: Engineering | I39: Not Started | J39: =IF($A39="","",IFERROR(INDEX(Lists!$B$2:$B$10,MATCH($I39,Lists!$A$2:$A$10,0)),"")) -> 0 | K39: 46275 | L39: 46295 | N39: =IF($A39="","",$L39-$K39+1) -> 21 | O39: =IF($A39="","",IF(OR($I39="Completed",$I39="Cancelled"),0,$L39-TODAY())) -> 66 | P39: DMT-037 | Q39: Low | S39: =IF($A39="","",IF(AND($O39<0,$I39<>"Completed",$I39<>"Cancelled"),1,0)) -> 0 | T39: =IF($A39="","",IF($I39="Completed",ROW(),"")) | U39: =IF($A39="","",IF(OR($I39="Not Started",$I39="Planning",$I39="Blocked"),ROW(),"")) -> 39
A40: DMT-039 | B40: Notifications | C40: الإشعارات | D40: إشعارات البريد الإلكتروني والرسائل | E40: دمج قوالب البريد الإلكتروني ورسائل SMS | F40: Medium | G40: لمياء العنزي | H40: Engineering | I40: Not Started | J40: =IF($A40="","",IFERROR(INDEX(Lists!$B$2:$B$10,MATCH($I40,Lists!$A$2:$A$10,0)),"")) -> 0 | K40: 46296 | L40: 46315 | N40: =IF($A40="","",$L40-$K40+1) -> 20 | O40: =IF($A40="","",IF(OR($I40="Completed",$I40="Cancelled"),0,$L40-TODAY())) -> 86 | P40: DMT-038 | Q40: Low | S40: =IF($A40="","",IF(AND($O40<0,$I40<>"Completed",$I40<>"Cancelled"),1,0)) -> 0 | T40: =IF($A40="","",IF($I40="Completed",ROW(),"")) | U40: =IF($A40="","",IF(OR($I40="Not Started",$I40="Planning",$I40="Blocked"),ROW(),"")) -> 40
...

Sheet Completed Work
A1: _RowRef | B1: Task | C1: Module | D1: Completed By | E1: Completion Date | F1: Duration | G1: Lessons Learned
A2: =IFERROR(SMALL('Master Task List'!$T$2:$T$600,1),"") -> 2 | B2: =IF($A2="","",INDEX('Master Task List'!$D:$D,$A2)) -> إعداد ميثاق المشروع | C2: =IF($A2="","",INDEX('Master Task List'!$B:$B,$A2)) -> Project Planning | D2: =IF($A2="","",INDEX('Master Task List'!$G:$G,$A2)) -> سارة العتيبي | E2: =IF($A2="","",INDEX('Master Task List'!$M:$M,$A2)) -> 46034 | F2: =IF($A2="","",INDEX('Master Task List'!$N:$N,$A2)) -> 10
A3: =IFERROR(SMALL('Master Task List'!$T$2:$T$600,2),"") -> 3 | B3: =IF($A3="","",INDEX('Master Task List'!$D:$D,$A3)) -> بناء خطة العمل الزمنية | C3: =IF($A3="","",INDEX('Master Task List'!$B:$B,$A3)) -> Project Planning | D3: =IF($A3="","",INDEX('Master Task List'!$G:$G,$A3)) -> سارة العتيبي | E3: =IF($A3="","",INDEX('Master Task List'!$M:$M,$A3)) -> 46049 | F3: =IF($A3="","",INDEX('Master Task List'!$N:$N,$A3)) -> 10
A4: =IFERROR(SMALL('Master Task List'!$T$2:$T$600,3),"") -> 4 | B4: =IF($A4="","",INDEX('Master Task List'!$D:$D,$A4)) -> تخصيص فريق العمل | C4: =IF($A4="","",INDEX('Master Task List'!$B:$B,$A4)) -> Project Planning | D4: =IF($A4="","",INDEX('Master Task List'!$G:$G,$A4)) -> سارة العتيبي | E4: =IF($A4="","",INDEX('Master Task List'!$M:$M,$A4)) -> 46054 | F4: =IF($A4="","",INDEX('Master Task List'!$N:$N,$A4)) -> 10
A5: =IFERROR(SMALL('Master Task List'!$T$2:$T$600,4),"") -> 5 | B5: =IF($A5="","",INDEX('Master Task List'!$D:$D,$A5)) -> جمع متطلبات الضمانات | C5: =IF($A5="","",INDEX('Master Task List'!$B:$B,$A5)) -> Business Analysis | D5: =IF($A5="","",INDEX('Master Task List'!$G:$G,$A5)) -> محمد القحطاني | E5: =IF($A5="","",INDEX('Master Task List'!$M:$M,$A5)) -> 46054 | F5: =IF($A5="","",INDEX('Master Task List'!$N:$N,$A5)) -> 15
A6: =IFERROR(SMALL('Master Task List'!$T$2:$T$600,5),"") -> 6 | B6: =IF($A6="","",INDEX('Master Task List'!$D:$D,$A6)) -> تحليل نموذج العمل | C6: =IF($A6="","",INDEX('Master Task List'!$B:$B,$A6)) -> Business Analysis | D6: =IF($A6="","",INDEX('Master Task List'!$G:$G,$A6)) -> محمد القحطاني | E6: =IF($A6="","",INDEX('Master Task List'!$M:$M,$A6)) -> 46075 | F6: =IF($A6="","",INDEX('Master Task List'!$N:$N,$A6)) -> 16
A7: =IFERROR(SMALL('Master Task List'!$T$2:$T$600,6),"") -> 7 | B7: =IF($A7="","",INDEX('Master Task List'!$D:$D,$A7)) -> إعداد وثيقة المتطلبات (BRD) | C7: =IF($A7="","",INDEX('Master Task List'!$B:$B,$A7)) -> Business Analysis | D7: =IF($A7="","",INDEX('Master Task List'!$G:$G,$A7)) -> محمد القحطاني | E7: =IF($A7="","",INDEX('Master Task List'!$M:$M,$A7)) -> 46085 | F7: =IF($A7="","",INDEX('Master Task List'!$N:$N,$A7)) -> 15
A8: =IFERROR(SMALL('Master Task List'!$T$2:$T$600,7),"") -> 8 | B8: =IF($A8="","",INDEX('Master Task List'!$D:$D,$A8)) -> بناء خرائط تدفق المستخدم | C8: =IF($A8="","",INDEX('Master Task List'!$B:$B,$A8)) -> UI/UX Design | D8: =IF($A8="","",INDEX('Master Task List'!$G:$G,$A8)) -> نورة الدوسري | E8: =IF($A8="","",INDEX('Master Task List'!$M:$M,$A8)) -> 46090 | F8: =IF($A8="","",INDEX('Master Task List'!$N:$N,$A8)) -> 20
A9: =IFERROR(SMALL('Master Task List'!$T$2:$T$600,8),"") -> 9 | B9: =IF($A9="","",INDEX('Master Task List'!$D:$D,$A9)) -> تصميم نظام التصميم (Design System) | C9: =IF($A9="","",INDEX('Master Task List'!$B:$B,$A9)) -> UI/UX Design | D9: =IF($A9="","",INDEX('Master Task List'!$G:$G,$A9)) -> نورة الدوسري | E9: =IF($A9="","",INDEX('Master Task List'!$M:$M,$A9)) -> 46115 | F9: =IF($A9="","",INDEX('Master Task List'!$N:$N,$A9)) -> 20
A10: =IFERROR(SMALL('Master Task List'!$T$2:$T$600,9),"") -> 10 | B10: =IF($A10="","",INDEX('Master Task List'!$D:$D,$A10)) -> تصميم النماذج التفاعلية (Prototype) | C10: =IF($A10="","",INDEX('Master Task List'!$B:$B,$A10)) -> UI/UX Design | D10: =IF($A10="","",INDEX('Master Task List'!$G:$G,$A10)) -> نورة الدوسري | E10: =IF($A10="","",INDEX('Master Task List'!$M:$M,$A10)) -> 46130 | F10: =IF($A10="","",INDEX('Master Task List'!$N:$N,$A10)) -> 20
A11: =IFERROR(SMALL('Master Task List'!$T$2:$T$600,10),"") -> 11 | B11: =IF($A11="","",INDEX('Master Task List'!$D:$D,$A11)) -> تصميم الشعار وتصميم الهوية | C11: =IF($A11="","",INDEX('Master Task List'!$B:$B,$A11)) -> Branding | D11: =IF($A11="","",INDEX('Master Task List'!$G:$G,$A11)) -> عبدالله الشمري | E11: =IF($A11="","",INDEX('Master Task List'!$M:$M,$A11)) -> 46085 | F11: =IF($A11="","",INDEX('Master Task List'!$N:$N,$A11)) -> 15
A12: =IFERROR(SMALL('Master Task List'!$T$2:$T$600,11),"") -> 12 | B12: =IF($A12="","",INDEX('Master Task List'!$D:$D,$A12)) -> تطوير دليل العلامة التجارية | C12: =IF($A12="","",INDEX('Master Task List'!$B:$B,$A12)) -> Branding | D12: =IF($A12="","",INDEX('Master Task List'!$G:$G,$A12)) -> عبدالله الشمري | E12: =IF($A12="","",INDEX('Master Task List'!$M:$M,$A12)) -> 46105 | F12: =IF($A12="","",INDEX('Master Task List'!$N:$N,$A12)) -> 15
A13: =IFERROR(SMALL('Master Task List'!$T$2:$T$600,12),"") -> 13 | B13: =IF($A13="","",INDEX('Master Task List'!$D:$D,$A13)) -> تصميم مواد تسويقية أولية | C13: =IF($A13="","",INDEX('Master Task List'!$B:$B,$A13)) -> Branding | D13: =IF($A13="","",INDEX('Master Task List'!$G:$G,$A13)) -> عبدالله الشمري | E13: =IF($A13="","",INDEX('Master Task List'!$M:$M,$A13)) -> 46115 | F13: =IF($A13="","",INDEX('Master Task List'!$N:$N,$A13)) -> 15
A14: =IFERROR(SMALL('Master Task List'!$T$2:$T$600,13),"") -> 20 | B14: =IF($A14="","",INDEX('Master Task List'!$D:$D,$A14)) -> تطوير تسجيل الدخول وكلمة المرور | C14: =IF($A14="","",INDEX('Master Task List'!$B:$B,$A14)) -> Authentication | D14: =IF($A14="","",INDEX('Master Task List'!$G:$G,$A14)) -> خالد الغامدي | E14: =IF($A14="","",INDEX('Master Task List'!$M:$M,$A14)) -> 46135 | F14: =IF($A14="","",INDEX('Master Task List'!$N:$N,$A14)) -> 20
A15: =IFERROR(SMALL('Master Task List'!$T$2:$T$600,14),"") -> 21 | B15: =IF($A15="","",INDEX('Master Task List'!$D:$D,$A15)) -> دمج المصادقة الثنائية (OTP) | C15: =IF($A15="","",INDEX('Master Task List'!$B:$B,$A15)) -> Authentication | D15: =IF($A15="","",INDEX('Master Task List'!$G:$G,$A15)) -> خالد الغامدي | E15: =IF($A15="","",INDEX('Master Task List'!$M:$M,$A15)) -> 46161 | F15: =IF($A15="","",INDEX('Master Task List'!$N:$N,$A15)) -> 21
A16: =IFERROR(SMALL('Master Task List'!$T$2:$T$600,15),"") -> 22 | B16: =IF($A16="","",INDEX('Master Task List'!$D:$D,$A16)) -> دمج تسجيل الدخول الموحد (SSO/نفاذ) | C16: =IF($A16="","",INDEX('Master Task List'!$B:$B,$A16)) -> Authentication | D16: =IF($A16="","",INDEX('Master Task List'!$G:$G,$A16)) -> خالد الغامدي | E16: =IF($A16="","",INDEX('Master Task List'!$M:$M,$A16)) -> 46176 | F16: =IF($A16="","",INDEX('Master Task List'!$N:$N,$A16)) -> 20
A17: =IFERROR(SMALL('Master Task List'!$T$2:$T$600,16),"") -> 23 | B17: =IF($A17="","",INDEX('Master Task List'!$D:$D,$A17)) -> بناء نظام الأدوار والصلاحيات | C17: =IF($A17="","",INDEX('Master Task List'!$B:$B,$A17)) -> User Management | D17: =IF($A17="","",INDEX('Master Task List'!$G:$G,$A17)) -> لمياء العنزي | E17: =IF($A17="","",INDEX('Master Task List'!$M:$M,$A17)) -> 46171 | F17: =IF($A17="","",INDEX('Master Task List'!$N:$N,$A17)) -> 25
A18: =IFERROR(SMALL('Master Task List'!$T$2:$T$600,17),"") | B18: =IF($A18="","",INDEX('Master Task List'!$D:$D,$A18)) | C18: =IF($A18="","",INDEX('Master Task List'!$B:$B,$A18)) | D18: =IF($A18="","",INDEX('Master Task List'!$G:$G,$A18)) | E18: =IF($A18="","",INDEX('Master Task List'!$M:$M,$A18)) | F18: =IF($A18="","",INDEX('Master Task List'!$N:$N,$A18))
A19: =IFERROR(SMALL('Master Task List'!$T$2:$T$600,18),"") | B19: =IF($A19="","",INDEX('Master Task List'!$D:$D,$A19)) | C19: =IF($A19="","",INDEX('Master Task List'!$B:$B,$A19)) | D19: =IF($A19="","",INDEX('Master Task List'!$G:$G,$A19)) | E19: =IF($A19="","",INDEX('Master Task List'!$M:$M,$A19)) | F19: =IF($A19="","",INDEX('Master Task List'!$N:$N,$A19))
A20: =IFERROR(SMALL('Master Task List'!$T$2:$T$600,19),"") | B20: =IF($A20="","",INDEX('Master Task List'!$D:$D,$A20)) | C20: =IF($A20="","",INDEX('Master Task List'!$B:$B,$A20)) | D20: =IF($A20="","",INDEX('Master Task List'!$G:$G,$A20)) | E20: =IF($A20="","",INDEX('Master Task List'!$M:$M,$A20)) | F20: =IF($A20="","",INDEX('Master Task List'!$N:$N,$A20))
A21: =IFERROR(SMALL('Master Task List'!$T$2:$T$600,20),"") | B21: =IF($A21="","",INDEX('Master Task List'!$D:$D,$A21)) | C21: =IF($A21="","",INDEX('Master Task List'!$B:$B,$A21)) | D21: =IF($A21="","",INDEX('Master Task List'!$G:$G,$A21)) | E21: =IF($A21="","",INDEX('Master Task List'!$M:$M,$A21)) | F21: =IF($A21="","",INDEX('Master Task List'!$N:$N,$A21))
A22: =IFERROR(SMALL('Master Task List'!$T$2:$T$600,21),"") | B22: =IF($A22="","",INDEX('Master Task List'!$D:$D,$A22)) | C22: =IF($A22="","",INDEX('Master Task List'!$B:$B,$A22)) | D22: =IF($A22="","",INDEX('Master Task List'!$G:$G,$A22)) | E22: =IF($A22="","",INDEX('Master Task List'!$M:$M,$A22)) | F22: =IF($A22="","",INDEX('Master Task List'!$N:$N,$A22))
A23: =IFERROR(SMALL('Master Task List'!$T$2:$T$600,22),"") | B23: =IF($A23="","",INDEX('Master Task List'!$D:$D,$A23)) | C23: =IF($A23="","",INDEX('Master Task List'!$B:$B,$A23)) | D23: =IF($A23="","",INDEX('Master Task List'!$G:$G,$A23)) | E23: =IF($A23="","",INDEX('Master Task List'!$M:$M,$A23)) | F23: =IF($A23="","",INDEX('Master Task List'!$N:$N,$A23))
A24: =IFERROR(SMALL('Master Task List'!$T$2:$T$600,23),"") | B24: =IF($A24="","",INDEX('Master Task List'!$D:$D,$A24)) | C24: =IF($A24="","",INDEX('Master Task List'!$B:$B,$A24)) | D24: =IF($A24="","",INDEX('Master Task List'!$G:$G,$A24)) | E24: =IF($A24="","",INDEX('Master Task List'!$M:$M,$A24)) | F24: =IF($A24="","",INDEX('Master Task List'!$N:$N,$A24))
A25: =IFERROR(SMALL('Master Task List'!$T$2:$T$600,24),"") | B25: =IF($A25="","",INDEX('Master Task List'!$D:$D,$A25)) | C25: =IF($A25="","",INDEX('Master Task List'!$B:$B,$A25)) | D25: =IF($A25="","",INDEX('Master Task List'!$G:$G,$A25)) | E25: =IF($A25="","",INDEX('Master Task List'!$M:$M,$A25)) | F25: =IF($A25="","",INDEX('Master Task List'!$N:$N,$A25))
A26: =IFERROR(SMALL('Master Task List'!$T$2:$T$600,25),"") | B26: =IF($A26="","",INDEX('Master Task List'!$D:$D,$A26)) | C26: =IF($A26="","",INDEX('Master Task List'!$B:$B,$A26)) | D26: =IF($A26="","",INDEX('Master Task List'!$G:$G,$A26)) | E26: =IF($A26="","",INDEX('Master Task List'!$M:$M,$A26)) | F26: =IF($A26="","",INDEX('Master Task List'!$N:$N,$A26))
A27: =IFERROR(SMALL('Master Task List'!$T$2:$T$600,26),"") | B27: =IF($A27="","",INDEX('Master Task List'!$D:$D,$A27)) | C27: =IF($A27="","",INDEX('Master Task List'!$B:$B,$A27)) | D27: =IF($A27="","",INDEX('Master Task List'!$G:$G,$A27)) | E27: =IF($A27="","",INDEX('Master Task List'!$M:$M,$A27)) | F27: =IF($A27="","",INDEX('Master Task List'!$N:$N,$A27))
A28: =IFERROR(SMALL('Master Task List'!$T$2:$T$600,27),"") | B28: =IF($A28="","",INDEX('Master Task List'!$D:$D,$A28)) | C28: =IF($A28="","",INDEX('Master Task List'!$B:$B,$A28)) | D28: =IF($A28="","",INDEX('Master Task List'!$G:$G,$A28)) | E28: =IF($A28="","",INDEX('Master Task List'!$M:$M,$A28)) | F28: =IF($A28="","",INDEX('Master Task List'!$N:$N,$A28))
A29: =IFERROR(SMALL('Master Task List'!$T$2:$T$600,28),"") | B29: =IF($A29="","",INDEX('Master Task List'!$D:$D,$A29)) | C29: =IF($A29="","",INDEX('Master Task List'!$B:$B,$A29)) | D29: =IF($A29="","",INDEX('Master Task List'!$G:$G,$A29)) | E29: =IF($A29="","",INDEX('Master Task List'!$M:$M,$A29)) | F29: =IF($A29="","",INDEX('Master Task List'!$N:$N,$A29))
A30: =IFERROR(SMALL('Master Task List'!$T$2:$T$600,29),"") | B30: =IF($A30="","",INDEX('Master Task List'!$D:$D,$A30)) | C30: =IF($A30="","",INDEX('Master Task List'!$B:$B,$A30)) | D30: =IF($A30="","",INDEX('Master Task List'!$G:$G,$A30)) | E30: =IF($A30="","",INDEX('Master Task List'!$M:$M,$A30)) | F30: =IF($A30="","",INDEX('Master Task List'!$N:$N,$A30))
A31: =IFERROR(SMALL('Master Task List'!$T$2:$T$600,30),"") | B31: =IF($A31="","",INDEX('Master Task List'!$D:$D,$A31)) | C31: =IF($A31="","",INDEX('Master Task List'!$B:$B,$A31)) | D31: =IF($A31="","",INDEX('Master Task List'!$G:$G,$A31)) | E31: =IF($A31="","",INDEX('Master Task List'!$M:$M,$A31)) | F31: =IF($A31="","",INDEX('Master Task List'!$N:$N,$A31))
A32: =IFERROR(SMALL('Master Task List'!$T$2:$T$600,31),"") | B32: =IF($A32="","",INDEX('Master Task List'!$D:$D,$A32)) | C32: =IF($A32="","",INDEX('Master Task List'!$B:$B,$A32)) | D32: =IF($A32="","",INDEX('Master Task List'!$G:$G,$A32)) | E32: =IF($A32="","",INDEX('Master Task List'!$M:$M,$A32)) | F32: =IF($A32="","",INDEX('Master Task List'!$N:$N,$A32))
A33: =IFERROR(SMALL('Master Task List'!$T$2:$T$600,32),"") | B33: =IF($A33="","",INDEX('Master Task List'!$D:$D,$A33)) | C33: =IF($A33="","",INDEX('Master Task List'!$B:$B,$A33)) | D33: =IF($A33="","",INDEX('Master Task List'!$G:$G,$A33)) | E33: =IF($A33="","",INDEX('Master Task List'!$M:$M,$A33)) | F33: =IF($A33="","",INDEX('Master Task List'!$N:$N,$A33))
A34: =IFERROR(SMALL('Master Task List'!$T$2:$T$600,33),"") | B34: =IF($A34="","",INDEX('Master Task List'!$D:$D,$A34)) | C34: =IF($A34="","",INDEX('Master Task List'!$B:$B,$A34)) | D34: =IF($A34="","",INDEX('Master Task List'!$G:$G,$A34)) | E34: =IF($A34="","",INDEX('Master Task List'!$M:$M,$A34)) | F34: =IF($A34="","",INDEX('Master Task List'!$N:$N,$A34))
A35: =IFERROR(SMALL('Master Task List'!$T$2:$T$600,34),"") | B35: =IF($A35="","",INDEX('Master Task List'!$D:$D,$A35)) | C35: =IF($A35="","",INDEX('Master Task List'!$B:$B,$A35)) | D35: =IF($A35="","",INDEX('Master Task List'!$G:$G,$A35)) | E35: =IF($A35="","",INDEX('Master Task List'!$M:$M,$A35)) | F35: =IF($A35="","",INDEX('Master Task List'!$N:$N,$A35))
A36: =IFERROR(SMALL('Master Task List'!$T$2:$T$600,35),"") | B36: =IF($A36="","",INDEX('Master Task List'!$D:$D,$A36)) | C36: =IF($A36="","",INDEX('Master Task List'!$B:$B,$A36)) | D36: =IF($A36="","",INDEX('Master Task List'!$G:$G,$A36)) | E36: =IF($A36="","",INDEX('Master Task List'!$M:$M,$A36)) | F36: =IF($A36="","",INDEX('Master Task List'!$N:$N,$A36))
A37: =IFERROR(SMALL('Master Task List'!$T$2:$T$600,36),"") | B37: =IF($A37="","",INDEX('Master Task List'!$D:$D,$A37)) | C37: =IF($A37="","",INDEX('Master Task List'!$B:$B,$A37)) | D37: =IF($A37="","",INDEX('Master Task List'!$G:$G,$A37)) | E37: =IF($A37="","",INDEX('Master Task List'!$M:$M,$A37)) | F37: =IF($A37="","",INDEX('Master Task List'!$N:$N,$A37))
A38: =IFERROR(SMALL('Master Task List'!$T$2:$T$600,37),"") | B38: =IF($A38="","",INDEX('Master Task List'!$D:$D,$A38)) | C38: =IF($A38="","",INDEX('Master Task List'!$B:$B,$A38)) | D38: =IF($A38="","",INDEX('Master Task List'!$G:$G,$A38)) | E38: =IF($A38="","",INDEX('Master Task List'!$M:$M,$A38)) | F38: =IF($A38="","",INDEX('Master Task List'!$N:$N,$A38))
A39: =IFERROR(SMALL('Master Task List'!$T$2:$T$600,38),"") | B39: =IF($A39="","",INDEX('Master Task List'!$D:$D,$A39)) | C39: =IF($A39="","",INDEX('Master Task List'!$B:$B,$A39)) | D39: =IF($A39="","",INDEX('Master Task List'!$G:$G,$A39)) | E39: =IF($A39="","",INDEX('Master Task List'!$M:$M,$A39)) | F39: =IF($A39="","",INDEX('Master Task List'!$N:$N,$A39))
A40: =IFERROR(SMALL('Master Task List'!$T$2:$T$600,39),"") | B40: =IF($A40="","",INDEX('Master Task List'!$D:$D,$A40)) | C40: =IF($A40="","",INDEX('Master Task List'!$B:$B,$A40)) | D40: =IF($A40="","",INDEX('Master Task List'!$G:$G,$A40)) | E40: =IF($A40="","",INDEX('Master Task List'!$M:$M,$A40)) | F40: =IF($A40="","",INDEX('Master Task List'!$N:$N,$A40))
...

Sheet Remaining Work
A1: _RowRef | B1: Task | C1: Module | D1: Priority | E1: Owner | F1: Status | G1: Estimated Effort (Days) | H1: Estimated Finish | I1: Dependency
A2: =IFERROR(SMALL('Master Task List'!$U$2:$U$600,1),"") -> 31 | B2: =IF($A2="","",INDEX('Master Task List'!$D:$D,$A2)) -> دمج بيانات المتاجر والموردين | C2: =IF($A2="","",INDEX('Master Task List'!$B:$B,$A2)) -> Guarantee Registration | D2: =IF($A2="","",INDEX('Master Task List'!$F:$F,$A2)) -> High | E2: =IF($A2="","",INDEX('Master Task List'!$G:$G,$A2)) -> لمياء العنزي | F2: =IF($A2="","",INDEX('Master Task List'!$I:$I,$A2)) -> Planning | G2: =IF($A2="","",INDEX('Master Task List'!$N:$N,$A2)) -> 30 | H2: =IF($A2="","",INDEX('Master Task List'!$L:$L,$A2)) -> 46284 | I2: =IF($A2="","",INDEX('Master Task List'!$P:$P,$A2)) -> DMT-029
A3: =IFERROR(SMALL('Master Task List'!$U$2:$U$600,2),"") -> 32 | B3: =IF($A3="","",INDEX('Master Task List'!$D:$D,$A3)) -> بناء خدمة التحقق الفوري | C3: =IF($A3="","",INDEX('Master Task List'!$B:$B,$A3)) -> Guarantee Verification | D3: =IF($A3="","",INDEX('Master Task List'!$F:$F,$A3)) -> Critical | E3: =IF($A3="","",INDEX('Master Task List'!$G:$G,$A3)) -> خالد الغامدي | F3: =IF($A3="","",INDEX('Master Task List'!$I:$I,$A3)) -> Planning | G3: =IF($A3="","",INDEX('Master Task List'!$N:$N,$A3)) -> 30 | H3: =IF($A3="","",INDEX('Master Task List'!$L:$L,$A3)) -> 46254 | I3: =IF($A3="","",INDEX('Master Task List'!$P:$P,$A3)) -> DMT-028
A4: =IFERROR(SMALL('Master Task List'!$U$2:$U$600,3),"") -> 33 | B4: =IF($A4="","",INDEX('Master Task List'!$D:$D,$A4)) -> دمج التحقق مع أنظمة الموردين | C4: =IF($A4="","",INDEX('Master Task List'!$B:$B,$A4)) -> Guarantee Verification | D4: =IF($A4="","",INDEX('Master Task List'!$F:$F,$A4)) -> High | E4: =IF($A4="","",INDEX('Master Task List'!$G:$G,$A4)) -> خالد الغامدي | F4: =IF($A4="","",INDEX('Master Task List'!$I:$I,$A4)) -> Blocked | G4: =IF($A4="","",INDEX('Master Task List'!$N:$N,$A4)) -> 31 | H4: =IF($A4="","",INDEX('Master Task List'!$L:$L,$A4)) -> 46285 | I4: =IF($A4="","",INDEX('Master Task List'!$P:$P,$A4)) -> DMT-031
A5: =IFERROR(SMALL('Master Task List'!$U$2:$U$600,4),"") -> 34 | B5: =IF($A5="","",INDEX('Master Task List'!$D:$D,$A5)) -> بناء سجل تدقيق التحقق | C5: =IF($A5="","",INDEX('Master Task List'!$B:$B,$A5)) -> Guarantee Verification | D5: =IF($A5="","",INDEX('Master Task List'!$F:$F,$A5)) -> High | E5: =IF($A5="","",INDEX('Master Task List'!$G:$G,$A5)) -> خالد الغامدي | F5: =IF($A5="","",INDEX('Master Task List'!$I:$I,$A5)) -> Not Started | G5: =IF($A5="","",INDEX('Master Task List'!$N:$N,$A5)) -> 30 | H5: =IF($A5="","",INDEX('Master Task List'!$L:$L,$A5)) -> 46315 | I5: =IF($A5="","",INDEX('Master Task List'!$P:$P,$A5)) -> DMT-032
A6: =IFERROR(SMALL('Master Task List'!$U$2:$U$600,5),"") -> 35 | B6: =IF($A6="","",INDEX('Master Task List'!$D:$D,$A6)) -> توليد رمز QR لكل ضمان | C6: =IF($A6="","",INDEX('Master Task List'!$B:$B,$A6)) -> QR Code System | D6: =IF($A6="","",INDEX('Master Task List'!$F:$F,$A6)) -> Medium | E6: =IF($A6="","",INDEX('Master Task List'!$G:$G,$A6)) -> فيصل المطيري | F6: =IF($A6="","",INDEX('Master Task List'!$I:$I,$A6)) -> Not Started | G6: =IF($A6="","",INDEX('Master Task List'!$N:$N,$A6)) -> 20 | H6: =IF($A6="","",INDEX('Master Task List'!$L:$L,$A6)) -> 46259 | I6: =IF($A6="","",INDEX('Master Task List'!$P:$P,$A6)) -> DMT-028
A7: =IFERROR(SMALL('Master Task List'!$U$2:$U$600,6),"") -> 36 | B7: =IF($A7="","",INDEX('Master Task List'!$D:$D,$A7)) -> تطوير ماسح QR داخل التطبيق | C7: =IF($A7="","",INDEX('Master Task List'!$B:$B,$A7)) -> QR Code System | D7: =IF($A7="","",INDEX('Master Task List'!$F:$F,$A7)) -> Medium | E7: =IF($A7="","",INDEX('Master Task List'!$G:$G,$A7)) -> فيصل المطيري | F7: =IF($A7="","",INDEX('Master Task List'!$I:$I,$A7)) -> Not Started | G7: =IF($A7="","",INDEX('Master Task List'!$N:$N,$A7)) -> 21 | H7: =IF($A7="","",INDEX('Master Task List'!$L:$L,$A7)) -> 46280 | I7: =IF($A7="","",INDEX('Master Task List'!$P:$P,$A7)) -> DMT-034
A8: =IFERROR(SMALL('Master Task List'!$U$2:$U$600,7),"") -> 37 | B8: =IF($A8="","",INDEX('Master Task List'!$D:$D,$A8)) -> طباعة وتوزيع ملصقات QR | C8: =IF($A8="","",INDEX('Master Task List'!$B:$B,$A8)) -> QR Code System | D8: =IF($A8="","",INDEX('Master Task List'!$F:$F,$A8)) -> Medium | E8: =IF($A8="","",INDEX('Master Task List'!$G:$G,$A8)) -> فيصل المطيري | F8: =IF($A8="","",INDEX('Master Task List'!$I:$I,$A8)) -> Not Started | G8: =IF($A8="","",INDEX('Master Task List'!$N:$N,$A8)) -> 20 | H8: =IF($A8="","",INDEX('Master Task List'!$L:$L,$A8)) -> 46300 | I8: =IF($A8="","",INDEX('Master Task List'!$P:$P,$A8)) -> DMT-035
A9: =IFERROR(SMALL('Master Task List'!$U$2:$U$600,8),"") -> 38 | B9: =IF($A9="","",INDEX('Master Task List'!$D:$D,$A9)) -> بناء محرك الإشعارات الفورية | C9: =IF($A9="","",INDEX('Master Task List'!$B:$B,$A9)) -> Notifications | D9: =IF($A9="","",INDEX('Master Task List'!$F:$F,$A9)) -> Low | E9: =IF($A9="","",INDEX('Master Task List'!$G:$G,$A9)) -> لمياء العنزي | F9: =IF($A9="","",INDEX('Master Task List'!$I:$I,$A9)) -> Not Started | G9: =IF($A9="","",INDEX('Master Task List'!$N:$N,$A9)) -> 20 | H9: =IF($A9="","",INDEX('Master Task List'!$L:$L,$A9)) -> 46274 | I9: =IF($A9="","",INDEX('Master Task List'!$P:$P,$A9)) -> DMT-022
A10: =IFERROR(SMALL('Master Task List'!$U$2:$U$600,9),"") -> 39 | B10: =IF($A10="","",INDEX('Master Task List'!$D:$D,$A10)) -> إشعارات انتهاء صلاحية الضمان | C10: =IF($A10="","",INDEX('Master Task List'!$B:$B,$A10)) -> Notifications | D10: =IF($A10="","",INDEX('Master Task List'!$F:$F,$A10)) -> Medium | E10: =IF($A10="","",INDEX('Master Task List'!$G:$G,$A10)) -> لمياء العنزي | F10: =IF($A10="","",INDEX('Master Task List'!$I:$I,$A10)) -> Not Started | G10: =IF($A10="","",INDEX('Master Task List'!$N:$N,$A10)) -> 21 | H10: =IF($A10="","",INDEX('Master Task List'!$L:$L,$A10)) -> 46295 | I10: =IF($A10="","",INDEX('Master Task List'!$P:$P,$A10)) -> DMT-037
A11: =IFERROR(SMALL('Master Task List'!$U$2:$U$600,10),"") -> 40 | B11: =IF($A11="","",INDEX('Master Task List'!$D:$D,$A11)) -> إشعارات البريد الإلكتروني والرسائل | C11: =IF($A11="","",INDEX('Master Task List'!$B:$B,$A11)) -> Notifications | D11: =IF($A11="","",INDEX('Master Task List'!$F:$F,$A11)) -> Medium | E11: =IF($A11="","",INDEX('Master Task List'!$G:$G,$A11)) -> لمياء العنزي | F11: =IF($A11="","",INDEX('Master Task List'!$I:$I,$A11)) -> Not Started | G11: =IF($A11="","",INDEX('Master Task List'!$N:$N,$A11)) -> 20 | H11: =IF($A11="","",INDEX('Master Task List'!$L:$L,$A11)) -> 46315 | I11: =IF($A11="","",INDEX('Master Task List'!$P:$P,$A11)) -> DMT-038
A12: =IFERROR(SMALL('Master Task List'!$U$2:$U$600,11),"") -> 41 | B12: =IF($A12="","",INDEX('Master Task List'!$D:$D,$A12)) -> بناء محرك بحث الضمانات | C12: =IF($A12="","",INDEX('Master Task List'!$B:$B,$A12)) -> Search | D12: =IF($A12="","",INDEX('Master Task List'!$F:$F,$A12)) -> Medium | E12: =IF($A12="","",INDEX('Master Task List'!$G:$G,$A12)) -> ريم الحربي | F12: =IF($A12="","",INDEX('Master Task List'!$I:$I,$A12)) -> Not Started | G12: =IF($A12="","",INDEX('Master Task List'!$N:$N,$A12)) -> 20 | H12: =IF($A12="","",INDEX('Master Task List'!$L:$L,$A12)) -> 46289 | I12: =IF($A12="","",INDEX('Master Task List'!$P:$P,$A12)) -> DMT-025
A13: =IFERROR(SMALL('Master Task List'!$U$2:$U$600,12),"") -> 42 | B13: =IF($A13="","",INDEX('Master Task List'!$D:$D,$A13)) -> إضافة الفلاتر المتقدمة | C13: =IF($A13="","",INDEX('Master Task List'!$B:$B,$A13)) -> Search | D13: =IF($A13="","",INDEX('Master Task List'!$F:$F,$A13)) -> Medium | E13: =IF($A13="","",INDEX('Master Task List'!$G:$G,$A13)) -> ريم الحربي | F13: =IF($A13="","",INDEX('Master Task List'!$I:$I,$A13)) -> Not Started | G13: =IF($A13="","",INDEX('Master Task List'!$N:$N,$A13)) -> 21 | H13: =IF($A13="","",INDEX('Master Task List'!$L:$L,$A13)) -> 46310 | I13: =IF($A13="","",INDEX('Master Task List'!$P:$P,$A13)) -> DMT-040
A14: =IFERROR(SMALL('Master Task List'!$U$2:$U$600,13),"") -> 43 | B14: =IF($A14="","",INDEX('Master Task List'!$D:$D,$A14)) -> تحسين أداء الفهرسة | C14: =IF($A14="","",INDEX('Master Task List'!$B:$B,$A14)) -> Search | D14: =IF($A14="","",INDEX('Master Task List'!$F:$F,$A14)) -> Medium | E14: =IF($A14="","",INDEX('Master Task List'!$G:$G,$A14)) -> ريم الحربي | F14: =IF($A14="","",INDEX('Master Task List'!$I:$I,$A14)) -> Not Started | G14: =IF($A14="","",INDEX('Master Task List'!$N:$N,$A14)) -> 20 | H14: =IF($A14="","",INDEX('Master Task List'!$L:$L,$A14)) -> 46330 | I14: =IF($A14="","",INDEX('Master Task List'!$P:$P,$A14)) -> DMT-041
A15: =IFERROR(SMALL('Master Task List'!$U$2:$U$600,14),"") -> 44 | B15: =IF($A15="","",INDEX('Master Task List'!$D:$D,$A15)) -> بناء تقارير الضمانات الأساسية | C15: =IF($A15="","",INDEX('Master Task List'!$B:$B,$A15)) -> Reports | D15: =IF($A15="","",INDEX('Master Task List'!$F:$F,$A15)) -> Medium | E15: =IF($A15="","",INDEX('Master Task List'!$G:$G,$A15)) -> منيرة القرني | F15: =IF($A15="","",INDEX('Master Task List'!$I:$I,$A15)) -> Not Started | G15: =IF($A15="","",INDEX('Master Task List'!$N:$N,$A15)) -> 25 | H15: =IF($A15="","",INDEX('Master Task List'!$L:$L,$A15)) -> 46309 | I15: =IF($A15="","",INDEX('Master Task List'!$P:$P,$A15)) -> DMT-031
A16: =IFERROR(SMALL('Master Task List'!$U$2:$U$600,15),"") -> 45 | B16: =IF($A16="","",INDEX('Master Task List'!$D:$D,$A16)) -> تقارير الأداء الإداري | C16: =IF($A16="","",INDEX('Master Task List'!$B:$B,$A16)) -> Reports | D16: =IF($A16="","",INDEX('Master Task List'!$F:$F,$A16)) -> Medium | E16: =IF($A16="","",INDEX('Master Task List'!$G:$G,$A16)) -> منيرة القرني | F16: =IF($A16="","",INDEX('Master Task List'!$I:$I,$A16)) -> Not Started | G16: =IF($A16="","",INDEX('Master Task List'!$N:$N,$A16)) -> 26 | H16: =IF($A16="","",INDEX('Master Task List'!$L:$L,$A16)) -> 46335 | I16: =IF($A16="","",INDEX('Master Task List'!$P:$P,$A16)) -> DMT-043
A17: =IFERROR(SMALL('Master Task List'!$U$2:$U$600,16),"") -> 46 | B17: =IF($A17="","",INDEX('Master Task List'!$D:$D,$A17)) -> جدولة التقارير الدورية | C17: =IF($A17="","",INDEX('Master Task List'!$B:$B,$A17)) -> Reports | D17: =IF($A17="","",INDEX('Master Task List'!$F:$F,$A17)) -> Medium | E17: =IF($A17="","",INDEX('Master Task List'!$G:$G,$A17)) -> منيرة القرني | F17: =IF($A17="","",INDEX('Master Task List'!$I:$I,$A17)) -> Not Started | G17: =IF($A17="","",INDEX('Master Task List'!$N:$N,$A17)) -> 25 | H17: =IF($A17="","",INDEX('Master Task List'!$L:$L,$A17)) -> 46360 | I17: =IF($A17="","",INDEX('Master Task List'!$P:$P,$A17)) -> DMT-044
